# name: asyncio.loop.call_ex 
loop.call_exception_handler(context)