# name: try:
    result = fu 
try:
    result = future.result(timeout)
except asyncio.TimeoutError:
    print('The coroutine took too long, cancelling the task...')
    future.cancel()
except Exception as exc:
    print(f'The coroutine raised an exception: {exc!r}')
else:
    print(f'The coroutine returned: {result!r}')