# name: >>> class C:
...     
>>> class C:
...     def __init__(self, extra):
...         self._extra_attributes = extra
...     def __getattr__(self, attr):
...         try:
...             return self._extra_attributes[attr]
...         except KeyError:
...             raise AttributeError(attr)
...
>>> C({}).x
Traceback (most recent call last):
  File "<stdin>", line 6, in __getattr__
KeyError: 'x'

During handling of the above exception, another exception occurred:

Traceback (most recent call last):
  File "<stdin>", line 1, in <module>
  File "<stdin>", line 8, in __getattr__
AttributeError: x